Workbook
Name ADES: #REF!
Name Applied: #REF!
Name CAPA: #REF!
Name Classification: #REF!
Name CloseDate: #REF!
Name ClosedOnTime: #REF!
Name code: #REF!
Name concerned: #REF!
Name CRD: OFFSET(#REF!,,,COUNT(#REF!),1)
Name CTS: OFFSET(#REF!,,,COUNT(#REF!),1)
Name Cuase: #REF!
Name cyrd: OFFSET(#REF!,,,COUNT(#REF!),1)
Name Date: #REF!
Name Description: #REF!
Name Editor: #REF!
Name Events: #REF!
Name Follow: #REF!
Name HSE: #REF!
Name Location: #REF!
Name MOAR: OFFSET(#REF!,,,COUNT(#REF!),1)
Name MRED: OFFSET(#REF!,,,COUNT(#REF!),1)
Name ncr: #REF!
Name NCRL: OFFSET(#REF!,,,COUNT(#REF!),1)
Name NCRLM: OFFSET(#REF!,,,COUNT(#REF!),1)
Name NL: OFFSET(#REF!,,,COUNT(#REF!),1)
Name NLY: OFFSET(#REF!,,,COUNT(#REF!),1)
Name NRD: OFFSET(#REF!,,,COUNT(#REF!),1)
Name nsn: OFFSET(#REF!,,,COUNT(#REF!),1)
Name NTS: OFFSET(#REF!,,,COUNT(#REF!),1)
Name nyrd: OFFSET(#REF!,,,COUNT(#REF!),1)
Name OAR: OFFSET(#REF!,,,COUNT(#REF!),1)
Name Observer: #REF!
Name OpenOverDue: #REF!
Name ORD: OFFSET(#REF!,,,COUNT(#REF!),1)
Name OSN: OFFSET(#REF!,,,COUNT(#REF!),1)
Name OTS: OFFSET(#REF!,,,COUNT(#REF!),1)
Name oyrd: OFFSET(#REF!,,,COUNT(#REF!),1)
Name Person: #REF!
Name PRD: OFFSET(#REF!,,,COUNT(#REF!),1)
Name Progress: #REF!
Name PSN: OFFSET(#REF!,,,COUNT(#REF!),1)
Name PTS: OFFSET(#REF!,,,COUNT(#REF!),1)
Name pyrd: OFFSET(#REF!,,,COUNT(#REF!),1)
Name RD: OFFSET(#REF!,,,COUNT(#REF!),1)
Name RecordDate: #REF!
Name RED: OFFSET(#REF!,,,COUNT(#REF!),1)
Name Severity: #REF!
Name Source: #REF!
Name state: #REF!
Name Tdate: #REF!
Name TRED: OFFSET(#REF!,,,COUNT(#REF!),1)
Name TS: OFFSET(#REF!,,,COUNT(#REF!),1)
Name Violation: #REF!
Name YOAR: OFFSET(#REF!,,,COUNT(#REF!),1)
Name yrd: OFFSET(#REF!,,,COUNT(#REF!),1)
Name الخط_الزمني_الأصلي_شهر: #N/A
Name الخط_الزمني_الأصلي_شهر1: #N/A
Name الخط_الزمني_الأصلي_شهر2: #N/A
Name الخط_الزمني_الأصلي_شهر3: #N/A
Name الورادي: #REF!

Sheet INDEX

Sheet houskeeping
A3: شهر | B3: (Multiple Items)
A5: عدد من المتابعة Follow Up | B5: السبب Cause | C5: المتابعة Follow Up
A7: الإدارة المتواجد بها الحالة | M7: =GETPIVOTDATA("المتابعة Follow Up",$A$5,"السبب Cause","عدم ترتيب و تنظيم") -> #REF!
A8: Grand Total

Sheet Description
A2: المتابعة Follow Up | B2: Opened
A3: شهر | B3: 45870
A5: منطقة الحدث | B5: وصف حالة عدم التطابق Description of non conformance | C5: درجة الخطورة | D5: الإدارة المتواجد بها الحالة | E5: عدد من المتابعة Follow Up
A6: عنبر ويب1 | B6: انسكاب وتدفق مياه التبريد لماكينة ويب6 علي الارض بعنبر ويب 1 | C6: عالى | D6: الويب | E6: 1
A7: Grand Total | E7: 1
B40: المتابعة Follow Up | C40: Opened
B41: شهر | C41: 45292
B43: منطقة الحدث | C43: وصف حالة عدم التطابق Description of non conformance | D43: درجة الخطورة | E43: الإدارة المتواجد بها الحالة | F43: عدد من المتابعة Follow Up
B44: المخزن الجديد | C44: لوحات الكهرباء الجديدة في العنبر الجديد تحتاج إلى غرفة عزل لها و تامين بطفايات فاير سيرش | D44: متوسط | E44: الادارة الهندسية | F44: 1
B45: المخزن القديم | C45: وجود اعمدة تالفة نتيجة اصتدام الكلاركات و الاخرى بدون زوايا حديد او كاوتش للحماية | D45: متوسط | E45: المخازن | F45: 1
B46: شارع الدشت | C46: مطبات وتكسير وعدم تواجد بلاعات صرف للمياه بشارع الدشت كما يوجد اغطية غرف تفتيش كابلات تالفة وتحتاج تغيير | D46: متوسط | E46: الادارة الهندسية | F46: 1
B47: الشوارع الخارجيه | C47: تلف بزوايا الحماية الحديد لارصفة الشوارع | D47: متوسط | E47: الادارة الهندسية | F47: 1
B48: Grand Total | F48: 4

Sheet ورقة2
A1: منطقة الحدث | B1: وصف حالة عدم التطابق Description of non conformance | C1: درجة الخطورة Degree of Risk
A2: عنبر الطبع شيت 1 | B2: ترشيح مياه من السقف بعنبر الطبع شيت بجوار مكتب الجودة | C2: عالى
A3: عنبر ويب 3 | B3: باب العنبر معلق من اعلى وليس محمل على دليل من اسفل | C3: عالى | E3: 1
A4: CTP | B4: وجود كابلات بطريقة عشوائية وبدون فليكسبل حماية او ترى كهرباء | C4: متوسط | E4: 2
A5: خراطيم الهواء بالماكينات | B5: خراطيم هواء بماكينات الإنتاج بدون مسدس تحكم | C5: متوسط | E5: 3
A6: البرج | B6: يوجد بواط كهرباء يحتاج إلى غطاء حماية + كابلات داتا تحتاج إلى تثبيت داخل الداكت الخاص بها | C6: عالى | E6: 4
B7: يوجد لوحة كهرباء تحتاج إلى غطاء حماية لها وتكملة تغطية كابلات الكهرباء بفليكسبل او دكت | C7: عالى | E7: 5
B8: لا يوجد لمبة بيان توضح اشغال الحمام مما يؤدي الى رفع حاجز الخصوصية عند الإستخدام | C8: متوسط
B9: غرفة ال'UPS لا يتوافر بها انظمة إطفاء ولا تهوية مناسبة لتغطية الأحمال الحرارية الناتجة من التشغيل ويجد داكت من التكيف المركزي و يفصل يوميا من الساعة السادسة مساء وحتى الساعة السابعة صباحا ولا حماية للوحات الكهرباء والتحكم ، | C9: عالى
B10: وجود ثلاجة ملتصقة بالحائط مباشرة بدون مراعاة المسافة البينية لها مع الحائط وبالإضافة انها امام لوحات كهرباء | C10: عالى

Sheet PT.MONTHS
A2: شهر | B2: (Multiple Items)
A3: السبب Cause | B3: (All)
A5: عدد من المتابعة Follow Up | B5: المتابعة Follow Up
A6: الإدارة المتواجد بها الحالة
A7: Grand Total
G11: =GETPIVOTDATA("المتابعة Follow Up",$A$5,"المتابعة Follow Up","Closed")+GETPIVOTDATA("المتابعة Follow Up",$A$5,"المتابعة Follow Up","Opened") -> #REF!

Sheet TEAM
A1: شهر | B1: 45839
A3: Row Labels | B3: عدد من وصف حالة عدم التطابق Description of non conformance
A4: Closed | B4: 12 | M4: 45292
A5: Opened | B5: 1
A6: Grand Total | B6: 13

Sheet PT2
A1: شهر | B1: 45870
F2: =GETPIVOTDATA("وصف حالة عدم التطابق Description of non conformance",$A$3) -> 12
A3: Row Labels | B3: عدد من وصف حالة عدم التطابق Description of non conformance
A4: Closed | B4: 11 | F4: =GETPIVOTDATA("وصف حالة عدم التطابق Description of non conformance",$A$3,"المتابعة Follow Up","Closed")/GETPIVOTDATA("وصف حالة عدم التطابق Description of non conformance",$A$3) -> 0.91666667
A5: Opened | B5: 1 | F5: =GETPIVOTDATA("وصف حالة عدم التطابق Description of non conformance",$A$3,"المتابعة Follow Up","Opened")/GETPIVOTDATA("وصف حالة عدم التطابق Description of non conformance",$A$3) -> 0.083333333
A6: Grand Total | B6: 12

Sheet NCR.S
A2: م | B2: شهر | C2: تاريخ الرصد Record Date | D2: مصدر الحالة Source | E2: 100 | F2: Column1 | G2: الكود Code | H2: Column2 | I2: النماذج المستخدمة Forms | J2: منطقة الحدث | K2: المعدة / الأداه | L2: الإدارة المتواجد بها الحالة | M2: كود الشخص القائم بالتبليغ | N2: إسم الشخص القائم بالتبليغ | O2: محرر التقرير SHE. Editor | P2: وصف حالة عدم التطابق Description of non conformance | Q2: السبب Cause | R2: الوردية Shift | S2: درجة الخطورة Degree of Risk | T2: Sent | U2: الاجراء التصحيحي / الوقائي Corrective /Preventive Action | V2: الإدارة المنفذة Applied by | W2: تاريخ التنفيذ Target Date | X2: on progress | Y2: المتابعة Follow Up | Z2: المتابع Followed by | AA2: تاريخ الإغلاق Date of Close | AB2: Closed On Time | AC2: في حالة توقــيع جـزاء عـلى الـعامل | AF2: ملاحظات Notes
A3: 1 | B3: 45839 | C3: 45845 | D3: قوائم الفحص | G3: N/1/7/7 | J3: المبني الاداري | K3: الداتا سنتر | L3: الشؤون الادارية | M3: =IF(Table142[[#This Row],[إسم الشخص القائم بالتبليغ]]="","",IFERROR(VLOOKUP(Table142[[#This Row],[إسم الشخص القائم بالتبليغ]],Sheet1!A:B,2,FALSE),"")) -> 13335 | N3: احمد مرسي مرسي | O3: محمود فضل الله | P3: تكرارتسريب مياه من وحدة التكييف بغرفة الداتا سنتر في المبني الإداري، حيث لوحظ سقوط مياه على بلجات الكهرباء وتجمع المياه علي الأرض بالقرب من كابلات النت والكهرباء | Q3: من المحتمل أن يكون ذلك نتيجة انسداد متكرر في خط التصريف، أو خلل في تصميم النظام، أو عدم كفاية أعمال الصيانة السابقة | S3: عالى | T3: OK | U3: اتخاذ إجراءات عاجلة ودائمة لمعالجة السبب الجذري للتسريب لمنع تكرار المشكلة | V3: الشؤون الادارية | X3: END | Y3: Closed | Z3: احمد مرسي مرسي | AA3: 14/7/2025
A4: 2 | B4: 45839 | C4: 45845 | D4: قوائم الفحص | G4: N/2/7/7 | J4: عنبر ويب2 | K4: ماكينة ويب 9 | L4: الويب | M4: =IF(Table142[[#This Row],[إسم الشخص القائم بالتبليغ]]="","",IFERROR(VLOOKUP(Table142[[#This Row],[إسم الشخص القائم بالتبليغ]],Sheet1!A:B,2,FALSE),"")) -> 14982 | N4: احمد سعد طلبة | O4: محمود فضل الله | P4: قطع في خرطوم الهواء الخاص باستيكر ويب 9 | Q4: عدم القيام بالصيانة الدورية بشكل منتظم | S4: متوسط | T4: OK | U4: اداء الصيانة الدورية بشكل منتظم | V4: الادارة الهندسية | X4: END | Y4: Closed | Z4: محمد فؤاد خليل | AA4: 45845
A5: 3 | B5: 45839 | C5: 45848 | D5: قوائم الفحص | G5: N/3/7/10 | J5: عنبر ويب 3 | K5: ماكينة ويب 9 | L5: الويب | M5: =IF(Table142[[#This Row],[إسم الشخص القائم بالتبليغ]]="","",IFERROR(VLOOKUP(Table142[[#This Row],[إسم الشخص القائم بالتبليغ]],Sheet1!A:B,2,FALSE),"")) -> 13335 | N5: احمد مرسي مرسي | O5: محمود فضل الله | P5: تسريب مياه من ثلاجة ويب 9 | Q5: عطل في الراجع الموجود بالثلاجة | S5: متوسط | T5: OK | U5: إجراء مايلزم من اصلاحات | V5: الادارة الهندسية | X5: END | Y5: Closed | Z5: محمد فؤاد خليل | AA5: 45848
A6: 4 | B6: 45839 | C6: 45850 | D6: قوائم الفحص | G6: N/4/7/12 | J6: عنبر ويب 3 | K6: ماكينة ويب 8 | L6: الويب | M6: =IF(Table142[[#This Row],[إسم الشخص القائم بالتبليغ]]="","",IFERROR(VLOOKUP(Table142[[#This Row],[إسم الشخص القائم بالتبليغ]],Sheet1!A:B,2,FALSE),"")) -> 13335 | N6: احمد مرسي مرسي | O6: محمود فضل الله | P6: وجود تسريب مياه من راجع صرف وحدة اللون الاسود | Q6: قطع في خرطوم صرف المياه في وحدة اللون الاسود | S6: متوسط | T6: OK | U6: إجراء مايلزم من اصلاحات | V6: الادارة الهندسية | Y6: Closed | Z6: احمد سعد طلبة | AA6: 45850
A7: 5 | B7: 45839 | C7: 45850 | D7: قوائم الفحص | G7: N/5/7/12 | J7: عنبر ويب2 | K7: ماكينة ويب 11 | L7: الويب | M7: =IF(Table142[[#This Row],[إسم الشخص القائم بالتبليغ]]="","",IFERROR(VLOOKUP(Table142[[#This Row],[إسم الشخص القائم بالتبليغ]],Sheet1!A:B,2,FALSE),"")) -> 13335 | N7: احمد مرسي مرسي | O7: محمود فضل الله | P7: تسريب زيت بجوار ويب 11 واسفل لوحة الكهرباء | Q7: قطع في خرطوم الزيت الموجود اسفل الماكينة | S7: متوسط | T7: OK | U7: إجراء مايلزم من اصلاحات | V7: الادارة الهندسية | X7: END | Y7: Closed | Z7: احمد سعد طلبة | AA7: 45850
A8: 6 | B8: 45839 | C8: 45852 | D8: قوائم الفحص | G8: N/6/7/14 | J8: عنبر ويب2 | K8: اويب 11 | L8: الويب | M8: =IF(Table142[[#This Row],[إسم الشخص القائم بالتبليغ]]="","",IFERROR(VLOOKUP(Table142[[#This Row],[إسم الشخص القائم بالتبليغ]],Sheet1!A:B,2,FALSE),"")) -> 15082 | N8: محمد موسى اسماعيل | O8: محمود فضل الله | P8: سلم معدني مكسور بماكينة ويب 11 وتخزين غير مؤقت لخشب التربيط علي الماكينة | Q8: وجود كسر في مفصلات السلم مع غياب اي إجراء للإبلاغ والإصلاح- غياب تنظيم تخزين المواد الخشبية | S8: عالى | T8: OK | U8: إجراء مايلزم من اصلاحات-إزالة خشب التربيط | V8: الانتاج | X8: END | Y8: Closed | Z8: محمد فؤاد خليل | AA8: 45856
A9: 7 | B9: 45839 | C9: 45852 | D9: قوائم الفحص | G9: N/7/7/14 | J9: المطابع | K9: الساحة | L9: الانتاج | M9: =IF(Table142[[#This Row],[إسم الشخص القائم بالتبليغ]]="","",IFERROR(VLOOKUP(Table142[[#This Row],[إسم الشخص القائم بالتبليغ]],Sheet1!A:B,2,FALSE),"")) -> 13335 | N9: احمد مرسي مرسي | O9: محمود فضل الله | P9: تسريب زيت من كلارك رقم 38 | Q9: عدم الانتظام في الصيانة الدورية | S9: متوسط | T9: OK | U9: اجراء الصيانة اللازمة | V9: الانتاج | X9: END | Y9: Closed | Z9: محمد فؤاد خليل | AA9: 45852
A10: 8 | B10: 45839 | C10: 45852 | D10: قوائم الفحص | G10: N/8/7/14 | J10: الكافتيريا | K10: غرفة التدخين | L10: الشؤون الادارية | M10: =IF(Table142[[#This Row],[إسم الشخص القائم بالتبليغ]]="","",IFERROR(VLOOKUP(Table142[[#This Row],[إسم الشخص القائم بالتبليغ]],Sheet1!A:B,2,FALSE),"")) -> 13335 | N10: احمد مرسي مرسي | O10: محمود فضل الله | P10: لا يوجد اضاءة في غرفة التدخين | Q10: تلف الكشاف | S10: متوسط | T10: OK | U10: تغيير الكشاف | V10: الشؤون الادارية | X10: END | Y10: Closed | Z10: علي صلاح علي | AA10: 45852
A11: 9 | B11: 45839 | C11: 45854 | D11: قوائم الفحص | G11: N/9/7/16 | J11: عنبر ويب 3 | K11: ويب 10 | L11: الادارة الهندسية | M11: =IF(Table142[[#This Row],[إسم الشخص القائم بالتبليغ]]="","",IFERROR(VLOOKUP(Table142[[#This Row],[إسم الشخص القائم بالتبليغ]],Sheet1!A:B,2,FALSE),"")) -> 13335 | N11: احمد مرسي مرسي | O11: محمود فضل الله | P11: لوحة كهرباء مفتوحة وبدون مرآة حماية عازلة مع تواجد سلوك مكشوفة بدون عزل | Q11: عدم الصيانة الدورية | S11: عالى | T11: OK | U11: عمل مايلزم من اصلاحات وحماية مناسبة | V11: الادارة الهندسية | X11: END | Y11: Closed | Z11: علي صلاح علي | AA11: 45854
A12: 10 | B12: 45839 | C12: 45855 | D12: قوائم الفحص | G12: N/10/7/17 | J12: عنبر ويب2 | K12: ويب 11 | L12: الويب | M12: =IF(Table142[[#This Row],[إسم الشخص القائم بالتبليغ]]="","",IFERROR(VLOOKUP(Table142[[#This Row],[إسم الشخص القائم بالتبليغ]],Sheet1!A:B,2,FALSE),"")) -> 13335 | N12: احمد مرسي مرسي | O12: محمود فضل الله | P12: تسريب سليكون اسفل لوحة الكهرباء وماكينة السلكون | Q12: عدم وضع ماكينة مادة السليكون بشكل جيد في برميل السليكون | S12: متوسط | T12: OK | U12: تنظيف المكان ووضع واستخدام ماكينة السليكون بشكل صحيح | V12: الادارة الهندسية | X12: END | Y12: Closed | Z12: احمد سعد طلبة | AA12: 45855
A13: 11 | B13: 45839 | C13: 45858 | D13: قوائم الفحص | G13: N/11/7/20 | J13: عنبر الطبع شيت 1 | K13: الطبع شيت | L13: طبع الشيت | M13: =IF(Table142[[#This Row],[إسم الشخص القائم بالتبليغ]]="","",IFERROR(VLOOKUP(Table142[[#This Row],[إسم الشخص القائم بالتبليغ]],Sheet1!A:B,2,FALSE),"")) -> 13335 | N13: احمد مرسي مرسي | O13: محمود فضل الله | P13: اضاءة ضعيفة | Q13: تلف كشافات | S13: متوسط | T13: OK | U13: تغيير الكشافات التالفة | V13: الشؤون الادارية | X13: END | Y13: Closed | Z13: احمد سعد طلبة | AA13: 45858
A14: 12 | B14: 45839 | C14: 45866 | D14: قوائم الفحص | G14: N/12/7/28 | J14: عنبر ويب 3 | K14: بجوار ماكينة ويب 7 | L14: الويب | M14: =IF(Table142[[#This Row],[إسم الشخص القائم بالتبليغ]]="","",IFERROR(VLOOKUP(Table142[[#This Row],[إسم الشخص القائم بالتبليغ]],Sheet1!A:B,2,FALSE),"")) -> 12212 | N14: علي صلاح علي | O14: محمود فضل الله | P14: انسكاب مادة السليكون | Q14: استخدام خاطئ من العاملين في غير الأغراض المخصصة له | S14: متوسط | T14: OK | U14: التوعية والالتزام بالاستخدام والتعامل الصحيح مع المواد الكيميائىة | V14: الويب | X14: END | Y14: Closed | Z14: احمد سعد طلبة | AA14: 45866
A15: 13 | B15: 45839 | C15: 45866 | D15: قوائم الفحص | G15: N/13/7/28 | J15: المخزن الجديد | K15: غرفة السيرفر | L15: IT | M15: =IF(Table142[[#This Row],[إسم الشخص القائم بالتبليغ]]="","",IFERROR(VLOOKUP(Table142[[#This Row],[إسم الشخص القائم بالتبليغ]],Sheet1!A:B,2,FALSE),"")) -> 15082 | N15: محمد موسى اسماعيل | O15: محمود فضل الله | P15: تخزين غير مطاابق داخل غرفة السيرفر | Q15: عدم توفر اماكن للتخزين | S15: متوسط | T15: OK | U15: نقل التخزين الغير مطابق الي مخزن مناسب والحفاظ علي نظافة المكان | V15: IT | Y15: Opened | Z15: محمد موسى اسماعيل | AA15: 45866
A16: 14 | B16: 45870 | C16: 45873 | D16: قوائم الفحص | G16: N/1/8/4 | J16: عنبر التجليد 1 | K16: كولبوس 2 | L16: التجليد | M16: =IF(Table142[[#This Row],[إسم الشخص القائم بالتبليغ]]="","",IFERROR(VLOOKUP(Table142[[#This Row],[إسم الشخص القائم بالتبليغ]],Sheet1!A:B,2,FALSE),"")) -> 12212 | N16: علي صلاح علي | O16: محمود فضل الله | P16: رفع ونقل ورص الملازم يدويا وصعود المتدربين (الطلبة) اعلي الملازم دون استخدام وسائل مناسبة او اشراف مباشر مما تسبب في سقوط الملازم | Q16: عدم وتوفر وسائل مناسبة لاعمال الرفع والنقل والرص غياب الاشراف المباشر | S16: عالى | T16: OK | U16: تخصيص افراد مدربين للقيام بهذه الاعمال- توفير ادوات ومعدات المناولة الامنة-تنظيم الرصات - الترتيب والنظافة المستمرة لموقع العمل | V16: التجليد | X16: END | Y16: Closed | Z16: علي صلاح علي | AA16: 45874
A17: 15 | B17: 45870 | C17: 45874 | D17: قوائم الفحص | G17: N/2/8/5 | J17: المطابع | K17: المطابع | L17: الادارة الهندسية | M17: =IF(Table142[[#This Row],[إسم الشخص القائم بالتبليغ]]="","",IFERROR(VLOOKUP(Table142[[#This Row],[إسم الشخص القائم بالتبليغ]],Sheet1!A:B,2,FALSE),"")) -> 13335 | N17: احمد مرسي مرسي | O17: محمود فضل الله | P17: كسر في باب صندوق الكلارك وتثبيت لوح كونتر داخل الصندوق | Q17: غياب الصيانة الدورية | S17: متوسط | T17: OK | U17: اصلاح الباب - تفعيل الصيانةالدورية | V17: الادارة الهندسية | X17: END | Y17: Closed | Z17: احمد مرسي مرسي | AA17: 45874
A18: 16 | B18: 45870 | C18: 45874 | D18: قوائم الفحص | G18: N/3/8/5 | J18: المكابس | K18: كولبوس 6 | L18: التجليد | M18: =IF(Table142[[#This Row],[إسم الشخص القائم بالتبليغ]]="","",IFERROR(VLOOKUP(Table142[[#This Row],[إسم الشخص القائم بالتبليغ]],Sheet1!A:B,2,FALSE),"")) -> 13335 | N18: احمد مرسي مرسي | O18: محمود فضل الله | P18: تسريب زيت اسفل مكبس كولبوس 6 | Q18: تلف خرطوم الزيت- غياب الصيانة الدورية | S18: متوسط | T18: OK | U18: تغيير الخرطوم - تفعيل الصيانة الدورية - ازالة اثار الانسكاب | V18: الادارة الهندسية | X18: END | Y18: Closed | Z18: احمد مرسي مرسي | AA18: 45874
A19: 17 | B19: 45870 | C19: 45876 | D19: قوائم الفحص | G19: N/4/8/7 | J19: البرج | K19: الدور التاسع | L19: الشؤون الادارية | M19: =IF(Table142[[#This Row],[إسم الشخص القائم بالتبليغ]]="","",IFERROR(VLOOKUP(Table142[[#This Row],[إسم الشخص القائم بالتبليغ]],Sheet1!A:B,2,FALSE),"")) -> 15006 | N19: محمد محمود عبدالعال | O19: محمود فضل الله | P19: كسر مفصلات شباك غرفة الاستوديو بالدور التاسع | Q19: سوء الاستخدام-غياب الصيانة الدورية | S19: متوسط | T19: OK | U19: اتباع تعليمات السلامة - تفعيل الصيانة الدورية - المور والمتابعة | V19: الشؤون الادارية | X19: END | Y19: Closed | Z19: محمد محمود عبدالعال | AA19: 45876
A20: 18 | B20: 45870 | C20: 45880 | D20: قوائم الفحص | G20: N/5/8/11 | J20: المخزن القديم | K20: المخزن القديم | L20: المخازن | M20: =IF(Table142[[#This Row],[إسم الشخص القائم بالتبليغ]]="","",IFERROR(VLOOKUP(Table142[[#This Row],[إسم الشخص القائم بالتبليغ]],Sheet1!A:B,2,FALSE),"")) -> 14548 | N20: كريم مجدي احمد | O20: محمود فضل الله | P20: تلف بخرطوم زيت التبريد لكلارك رقم 216 | Q20: سوء الاستخدام- غياب الصيانة الدورية | S20: متوسط | T20: OK | U20: تغيير الخرطوم - اتباع تعليمات التشغيل والصيانة - تفعيل الصيانة الدورية | V20: المخازن | X20: END | Y20: Closed | Z20: كريم مجدي احمد | AA20: 45880
A21: 19 | B21: 45870 | C21: 45882 | D21: قوائم الفحص | G21: N/6/8/13 | J21: عنبر ويب1 | K21: ويب 6 | L21: الويب | M21: =IF(Table142[[#This Row],[إسم الشخص القائم بالتبليغ]]="","",IFERROR(VLOOKUP(Table142[[#This Row],[إسم الشخص القائم بالتبليغ]],Sheet1!A:B,2,FALSE),"")) -> 12212 | N21: علي صلاح علي | O21: محمود فضل الله | P21: انسكاب وتدفق مياه التبريد لماكينة ويب6 علي الارض بعنبر ويب 1 | Q21: خلل في نظام رجوع مياه التبريد للماكينة بالاضافة الي عدم وجود نظام تصريف او بيارة صرف تجميع المياه | S21: عالى | T21: OK | U21: فحص الماكينة - اصلاح نظام التبريد - تصميم نظام تصريف مناسب | V21: الادارة الهندسية | Y21: Opened | Z21: علي صلاح علي
A22: 20 | B22: 45870 | C22: 45888 | D22: قوائم الفحص | G22: N/7/8/19 | J22: عنبر ويب2 | K22: باب طوارئ ويب 2 | L22: الادارة الهندسية | M22: =IF(Table142[[#This Row],[إسم الشخص القائم بالتبليغ]]="","",IFERROR(VLOOKUP(Table142[[#This Row],[إسم الشخص القائم بالتبليغ]],Sheet1!A:B,2,FALSE),"")) -> 13335 | N22: احمد مرسي مرسي | O22: محمود فضل الله | P22: وجودصاج ايل للسقوط باب مدخل ويب 2 | Q22: غياب المتابعة والصيانة | S22: متوسط | T22: OK | U22: ازالة الصاج من اعلي الباب-اتباع تعليمات السلامة - تفعيل الصيانة الدورية - المرور والمتابعة | V22: الادارة الهندسية | X22: END | Y22: Closed | Z22: احمد مرسي مرسي | AA22: 45888
A23: 21 | B23: 45870 | C23: 45888 | D23: قوائم الفحص | G23: N/8/8/19 | J23: عنبر ويب 3 | K23: ويب 2 | L23: الادارة الهندسية | M23: =IF(Table142[[#This Row],[إسم الشخص القائم بالتبليغ]]="","",IFERROR(VLOOKUP(Table142[[#This Row],[إسم الشخص القائم بالتبليغ]],Sheet1!A:B,2,FALSE),"")) -> 14982 | N23: احمد سعد طلبة | O23: محمود فضل الله | P23: تسريب مياه من ماسورة المياه لويب 2،9 | Q23: تآكل الماسورة | S23: متوسط | T23: OK | U23: عمل الصيانة اللازمة | V23: الادارة الهندسية | X23: END | Y23: Closed | Z23: احمد سعد طلبة | AA23: 45888
A24: 22 | B24: 45870 | C24: 45888 | D24: قوائم الفحص | G24: N/9/8/19 | J24: غرف الغاز | K24: شارع الدشت | L24: الادارة الهندسية | M24: =IF(Table142[[#This Row],[إسم الشخص القائم بالتبليغ]]="","",IFERROR(VLOOKUP(Table142[[#This Row],[إسم الشخص القائم بالتبليغ]],Sheet1!A:B,2,FALSE),"")) -> 14304 | N24: علاء عنتر محمد | O24: محمود فضل الله | P24: تشوينات حديد بجوار غرفة الغاز | Q24: ضيق المساحات التخزينية | S24: متوسط | T24: OK | U24: ازالة التشوينات ونقلها الي المخزن المناسب - اتباع تعليمات السلامة | V24: الادارة الهندسية | X24: END | Y24: Closed | Z24: علاء عنتر محمد | AA24: 45888
A25: 23 | B25: 45870 | C25: 45896 | D25: قوائم الفحص | G25: N/10/8/27 | J25: السور الامامي | K25: البوابات | L25: الشؤون الادارية | M25: =IF(Table142[[#This Row],[إسم الشخص القائم بالتبليغ]]="","",IFERROR(VLOOKUP(Table142[[#This Row],[إسم الشخص القائم بالتبليغ]],Sheet1!A:B,2,FALSE),"")) -> 15082 | N25: محمد موسى اسماعيل | O25: محمود فضل الله | P25: عد ترتيب وتنظيم كابلات الكهرباء | Q25: غياب الصيانة الدورية | S25: متوسط | T25: OK | U25: ترتيب وتنظيم الكابلات مع المتابعة الدورية | V25: الشؤون الادارية | X25: END | Y25: Closed | Z25: محمد موسى اسماعيل | AA25: 45896
A26: 24 | B26: 45870 | C26: 45897 | D26: قوائم الفحص | G26: N/11/8/28 | J26: عنبر ويب1 | K26: ويب 6 | L26: الويب | M26: =IF(Table142[[#This Row],[إسم الشخص القائم بالتبليغ]]="","",IFERROR(VLOOKUP(Table142[[#This Row],[إسم الشخص القائم بالتبليغ]],Sheet1!A:B,2,FALSE),"")) -> 13335 | N26: احمد مرسي مرسي | O26: محمود فضل الله | P26: تسريب مياه من ثلاجة ويب 6 | Q26: ثقب في الوصلة الحديد لخرطوم مياه الثلاجة | S26: عالى | T26: OK | U26: عمل الصيانة اللازمة مع تفعيل الصيانة الدورية - نظافة المكان | V26: الادارة الهندسية | X26: END | Y26: Closed | Z26: احمد مرسي مرسي | AA26: 45897
A27: 25 | B27: 45870 | C27: 45897 | D27: قوائم الفحص | G27: N/12/8/28 | J27: عنبر ويب 3 | K27: تانك الحبر | L27: الويب | M27: =IF(Table142[[#This Row],[إسم الشخص القائم بالتبليغ]]="","",IFERROR(VLOOKUP(Table142[[#This Row],[إسم الشخص القائم بالتبليغ]],Sheet1!A:B,2,FALSE),"")) -> 13335 | N27: احمد مرسي مرسي | O27: محمود فضل الله | P27: تسريب حبر من تانك اللون الاحمر | Q27: كسر في طبة التانك - غياب الصيانة الدورية | S27: عالى | T27: OK | U27: تغيير الطبة وعمل مايلزم من صيانة - نظافة المكان | V27: الادارة الهندسية | X27: END | Y27: Closed | Z27: احمد مرسي مرسي | AA27: 45897
A28: 215 | M28: =IF(Table142[[#This Row],[إسم الشخص القائم بالتبليغ]]="","",IFERROR(VLOOKUP(Table142[[#This Row],[إسم الشخص القائم بالتبليغ]],Sheet1!A:B,2,FALSE),""))
A29: 216 | M29: =IF(Table142[[#This Row],[إسم الشخص القائم بالتبليغ]]="","",IFERROR(VLOOKUP(Table142[[#This Row],[إسم الشخص القائم بالتبليغ]],Sheet1!A:B,2,FALSE),""))
A30: 217 | M30: =IF(Table142[[#This Row],[إسم الشخص القائم بالتبليغ]]="","",IFERROR(VLOOKUP(Table142[[#This Row],[إسم الشخص القائم بالتبليغ]],Sheet1!A:B,2,FALSE),""))
A31: 218 | M31: =IF(Table142[[#This Row],[إسم الشخص القائم بالتبليغ]]="","",IFERROR(VLOOKUP(Table142[[#This Row],[إسم الشخص القائم بالتبليغ]],Sheet1!A:B,2,FALSE),""))
A32: 219 | M32: =IF(Table142[[#This Row],[إسم الشخص القائم بالتبليغ]]="","",IFERROR(VLOOKUP(Table142[[#This Row],[إسم الشخص القائم بالتبليغ]],Sheet1!A:B,2,FALSE),""))
A33: 220 | M33: =IF(Table142[[#This Row],[إسم الشخص القائم بالتبليغ]]="","",IFERROR(VLOOKUP(Table142[[#This Row],[إسم الشخص القائم بالتبليغ]],Sheet1!A:B,2,FALSE),""))
A34: 221 | M34: =IF(Table142[[#This Row],[إسم الشخص القائم بالتبليغ]]="","",IFERROR(VLOOKUP(Table142[[#This Row],[إسم الشخص القائم بالتبليغ]],Sheet1!A:B,2,FALSE),""))
A35: 222 | M35: =IF(Table142[[#This Row],[إسم الشخص القائم بالتبليغ]]="","",IFERROR(VLOOKUP(Table142[[#This Row],[إسم الشخص القائم بالتبليغ]],Sheet1!A:B,2,FALSE),""))
A36: 223 | M36: =IF(Table142[[#This Row],[إسم الشخص القائم بالتبليغ]]="","",IFERROR(VLOOKUP(Table142[[#This Row],[إسم الشخص القائم بالتبليغ]],Sheet1!A:B,2,FALSE),""))
A37: 224 | M37: =IF(Table142[[#This Row],[إسم الشخص القائم بالتبليغ]]="","",IFERROR(VLOOKUP(Table142[[#This Row],[إسم الشخص القائم بالتبليغ]],Sheet1!A:B,2,FALSE),""))
A38: 225 | M38: =IF(Table142[[#This Row],[إسم الشخص القائم بالتبليغ]]="","",IFERROR(VLOOKUP(Table142[[#This Row],[إسم الشخص القائم بالتبليغ]],Sheet1!A:B,2,FALSE),""))
A39: 226 | M39: =IF(Table142[[#This Row],[إسم الشخص القائم بالتبليغ]]="","",IFERROR(VLOOKUP(Table142[[#This Row],[إسم الشخص القائم بالتبليغ]],Sheet1!A:B,2,FALSE),""))
... A116: 303 | M116: =IF(Table142[[#This Row],[إسم الشخص القائم بالتبليغ]]="","",IFERROR(VLOOKUP(Table142[[#This Row],[إسم الشخص القائم بالتبليغ]],Sheet1!A:B,2,FALSE),""))
M117: =IF(Table142[[#This Row],[إسم الشخص القائم بالتبليغ]]="","",IFERROR(VLOOKUP(Table142[[#This Row],[إسم الشخص القائم بالتبليغ]],Sheet1!A:B,2,FALSE),""))
...

Sheet Sheet1
A1: اللواء/ هشام صادق | B1: 14655
A2: محمد فؤاد خليل | B2: 10728
A3: علي صلاح علي | B3: 12212
A4: احمد مرسي مرسي | B4: 13335
A5: هاني لطفي المليجي | B5: 13411
A6: كريم مجدي احمد | B6: 14548
A7: احمد محمود بكري | B7: 14605
A8: احمد سعد طلبة | B8: 14982
A9: علاء عنتر محمد | B9: 14304
A10: محمود مصطفى سيد | B10: 15074
A11: محمد محمود عبدالعال | B11: 15006
A12: محمد موسى اسماعيل | B12: 15082
... A14: محمود فضل الله | B14: 15905

Sheet ورقة1
A3: م | B3: شهر | C3: تاريخ الرصد Record Date | D3: مصدر الحالة Source | E3: 100 | F3: Column1 | G3: الكود Code | H3: Column2 | I3: النماذج المستخدمة Forms | J3: منطقة الحدث | K3: المعدة / الأداه | L3: الإدارة المتواجد بها الحالة | M3: مكتشف الحالة / المتضرر Discovered by / Affected | N3: إسم الشخص القائم بالتبليغ | O3: محرر التقرير SHE. Editor | P3: وصف حالة عدم التطابق Description of non conformance | Q3: السبب Cause | R3: الوردية Shift | S3: درجة الخطورة Degree of Risk | T3: Sent | U3: الاجراء التصحيحي / الوقائي Corrective /Preventive Action | V3: الإدارة المنفذة Applied by | W3: تاريخ التنفيذ Target Date | X3: on progress | Y3: المتابعة Follow Up | Z3: المتابع Followed by | AA3: تاريخ الإغلاق Date of Close | AB3: Closed On Time
A4: 1 | B4: 44866 | C4: 44867 | D4: تفتيش داخلى | G4: 44867 | H4: -1 | J4: عنبر ويب1 | L4: الويب | P4: مدخنة ويب 4 بدون عزل حراري | Q4: تصرف غير آمن | R4: أولى | S4: متوسط | T4: OK | U4: تركيب العزل الحراري للمدخنة والمتابعة المستمرة للحالات المسشابه | V4: الادارة الهندسية | W4: 44603 | Y4: Closed | AA4: 44867 | AB4: On Time
A5: 2 | B5: 44866 | C5: 44631 | D5: تفتيش داخلى | G5: 44631 | H5: -1 | J5: عنبر التجليد 2 | L5: التجليد | P5: اثناء مرور مشرف السلامة تلاحظ صوت عالى من ماكينة كولبوس2 نتيجة لتسريب الهواء | Q5: تصرف غير آمن | R5: ثانية | S5: متوسط | T5: OK | U5: تغيير الخرطوم التالف من قبل إدارة الصيانة | V5: الادارة الهندسية | W5: 44631 | Y5: Closed | AA5: 44631 | AB5: On Time
A6: 3 | B6: 44866 | C6: 44873 | D6: تفتيش داخلى | G6: 44784 | H6: -1 | J6: عنبر ويب1 | L6: الويب | P6: تسريب مياه وزيت من ماكينة ويب6 | Q6: تصرف غير آمن | R6: ثانية | S6: عالي | T6: OK | U6: تم الابلاغ وتم عمل الصيانة اللازمة | V6: الادارة الهندسية | W6: 44784 | Y6: Closed | AA6: 44784 | AB6: On Time
A7: =A6+1 -> 4 | B7: 44866 | C7: 44876 | D7: تفتيش داخلى | G7: 44876 | H7: -1 | J7: المخزن الجديد | L7: المخازن | P7: وجود ماكينات التغليف بعنبر رقم2 بجوار المنتج | Q7: تصرف غير آمن | R7: أولى | S7: عالي | T7: OK | U7: توفير مكان امن لماكينات الشرنك بعيداً عن المنتج | V7: المخازن | Y7: Opened
A8: =A7+1 -> 5 | B8: 44866 | C8: 44876 | D8: تفتيش داخلى | G8: 44876 | H8: -1 | J8: المخزن الجديد | L8: المخازن | P8: وجود سخان كهربي بمكتب الامن لا ينطبق علية شروط السلامة | Q8: تصرف غير أمن | R8: أولى | S8: عالي | T8: OK | U8: تم ازالة السخان فى الحال | V8: المخازن | W8: 44876 | Y8: Closed | AA8: 44876 | AB8: On Time
A9: =A8+1 -> 6 | B9: 44896 | C9: 44897 | D9: تفتيش داخلى | G9: 44604 | H9: -1 | J9: عنبر التجليد 1 | L9: التجليد | P9: وجود تخزينات من الكرتون واكياس الاستريتش بجوار لوحات الكهرباء بجوار ماكينة التجليد | Q9: عدم ترتيب و تنظيم | R9: أولى | S9: متوسط | T9: OK | U9: ازالة التخزينات والتنبية على العاملين بعد رص الخامات والمنتج بجوار لوحات الكهرباء | V9: التجليد | W9: 44604 | Y9: Closed | AA9: 44604 | AB9: On Time
A10: =A9+1 -> 7 | B10: 44896 | C10: 44899 | D10: تفتيش داخلى | G10: 44663 | H10: -1 | J10: شارع الدشت | L10: الادارة الهندسية | P10: مواسير وعدادات الغاز المغذية لعنابر الانتاج ليس بوضع امن | Q10: وضع غير أمن | R10: أولى | S10: عالي | T10: OK | U10: تم التواصل مع مسئولي الادارة الهندسية بعمل حواجز حماية لجميع الاوضاع المشابه | V10: الادارة الهندسية | W10: 44663 | Y10: Closed | AA10: 44816
A11: =A10+1 -> 8 | B11: 44896 | C11: 44903 | D11: تفتيش داخلى | G11: 44785 | H11: -1 | J11: غرف الغاز | L11: الويب | P11: وجود تخزينات منتج امام غرف الغاز | Q11: عدم ترتيب و تنظيم | R11: ثانية | S11: متوسط | T11: OK | U11: التواصل مع مشرف المنطقة وشرح خطورة الموقف من قبل مشرف السلامة والتنبية علية بعدم التخزين مره اخرى | V11: الانتاج | W11: 44785 | Y11: Closed | AA11: 44785 | AB11: On Time
A12: =A11+1 -> 9 | B12: 44896 | C12: 44903 | D12: حادث وشيك | G12: 44785 | H12: -2 | J12: عنبر ويب2 | L12: الانتاج | P12: اثناء رفع سائق الكلارك للبكر وتوصيلة الى ماكينات الويب اصطدم بأحدى محابس الحريق(كسر الطارة الخارجية) | Q12: وضع غير أمن | R12: أولى | S12: عالي | T12: OK | U12: تم تركيب الطارة والتواصل مع مسئولي الانتاج بعد رص الخامات والمنتج اسفل محابس الحريق | V12: الانتاج | W12: 44785 | Y12: Closed | AA12: 44846 | AB12: On Time
A13: =A12+1 -> 10 | B13: 44896 | C13: 44905 | D13: تفتيش داخلى | G13: 44846 | H13: -1 | J13: المخزن القديم | L13: السلامة و الصحة | P13: ترشيح مياه من حائط خزان الحريق | Q13: وضع غير أمن | R13: أولى | S13: عالي | T13: OK | U13: التواصل مع الادارة الهندسية لتوفير احدى الشركات لعمل الاجراء التصحيحي اللازم | V13: الادارة الهندسية | W13: 44877 | Y13: Closed | AA13: 20-12-2022
A14: =A13+1 -> 11 | B14: 44896 | C14: 44916 | D14: تفتيش داخلى | G14: 21-12-2022 | H14: -1 | J14: عنبر ويب2 | L14: الادارة الهندسية | P14: تسريب مياه من مجر صرف الامطار داخل عنبر ويب2 نتيجة (ارتفاع فتحات الصرف بالمجر من اعلى) | Q14: وضع غير أمن | R14: أولى | S14: عالي | T14: OK | U14: تم ارسال ميل للادارة المختصة لارسال احدى الشركات المختصة بعمل اللازم | V14: الادارة الهندسية | W14: 21-12-2022 | Y14: Opened
A15: =A14+1 -> 12 | B15: 44896 | C15: 44924 | D15: تفتيش داخلى | G15: 29-12-2022 | H15: -1 | J15: المخزن القديم | L15: المخازن | P15: مشمعات واستريتش بلاستيك بشكل كثيف بالمخزن | Q15: عدم ترتيب و تنظيم | R15: أولى | S15: متوسط | U15: التواصل مع المسئولين بالمخزن وتم رفع التخزينات | V15: المخازن | W15: 29-12-2022 | Y15: Closed | AA15: 29-12-2022
A16: =A15+1 -> 13 | B16: 44927 | C16: 44930 | D16: تفتيش داخلى | G16: 44930 | H16: -6 | J16: عنبر ويب 3 | K16: ويب7 | L16: الويب | P16: وجود تسريب مياه وزيت بجوار ويب 7 | Q16: تصرف غير أمن | R16: أولى | S16: متوسط | T16: OK | U16: تنظيف المكان و ازالة الزيت والمياه من على الارض | V16: الويب | W16: 45017 | X16: end | Y16: Closed | Z16: م/ادهم مصطفى | AA16: 45017 | AB16: OK
A17: =A16+1 -> 14 | B17: 44927 | C17: 44930 | D17: تفتيش داخلى | G17: 44930 | H17: -7 | J17: عنبر التجليد 1 | K17: امام المكبس | L17: التجليد | P17: وجود بشر كثير اسفل المكبس | Q17: وضع غير أمن | R17: أولى | S17: عالي | T17: OK | U17: تنظيف المكان جيدا من البشر , اصلاح اي اعطال طارئة بالمكبس او مراوح السحب | V17: الادارة الهندسية | W17: 29/1/2023 | X17: end | Y17: Closed | Z17: م/ادهم مصطفى | AA17: 29/1/2023 | AB17: ok
A18: =A17+1 -> 15 | B18: 44927 | C18: 44936 | D18: تفتيش داخلى | G18: 44936 | H18: -1 | J18: عنبر ويب1 | K18: ماكينة الشرينك | L18: الادارة الهندسية | P18: كابل تالف الخاص بماكينة الشرينك ويحتاج الى تغيير , بجوار سيتما 1,2 | Q18: وضع غير أمن | R18: أولى | S18: عالي | T18: OK | U18: تغيير الكابل التالف في اسرع وقت و المتابعة الدورية لصيانة الماكينة | V18: الادارة الهندسية | W18: 45200 | X18: end | Y18: Closed | Z18: م/ادهم مصطفى | AA18: 45200 | AB18: ok
A19: =A18+1 -> 16 | B19: 44927 | C19: 44938 | D19: تفتيش داخلى | G19: 44938 | H19: -1 | J19: عنبر ويب2 | K19: اعلى عنبر ويب 2 | L19: الادارة الهندسية | P19: كابل كهرباء غير مشدود على ترى الكهرباء و يمر من اعلى المواسير | Q19: وضع غير أمن | R19: أولى | S19: متوسط | T19: OK | U19: تعديل مسار كابل الكهرباء و شده على ترى الكهرباء | V19: الادارة الهندسية | W19: 27/1/2023 | X19: end | Y19: Closed | Z19: م/ادهم مصطفى | AA19: 27/1/2023 | AB19: ok
A20: =A19+1 -> 17 | B20: 44927 | C20: 44938 | D20: تفتيش داخلى | G20: 44938 | H20: -2 | J20: عنبر ويب2 | K20: عنبر ويب2 | L20: الادارة الهندسية | P20: وجود مكن تالف وقطع غيار تالفة في منتصف العنبر | Q20: عدم ترتيب و تنظيم | R20: أولى | S20: متوسط | T20: OK | U20: ازالة اي مخلفات من قطع الغيار او المكن التالف و التخلص منه بشكل امن وسليم | V20: الادارة الهندسية | X20: yes | Y20: Opened | Z20: م/ادهم مصطفى | AB20: DELAYED
A21: =A20+1 -> 18 | B21: 44927 | C21: 44938 | D21: تفتيش داخلى | G21: 44938 | H21: -3 | J21: عنبر ويب2 | K21: تونجر الشحن | L21: الادارة الهندسية | P21: وجود تونجر شحن بطاريات الكلاركات الكهرباء بمنتصف العنبر و بجوار المخلفات و بدون توفير اماكن لشحن الكلاركات او اجراءات وقائية | Q21: وضع غير أمن | R21: أولى | S21: متوسط | T21: OK | U21: تغيير مكان الشحن للكلاركات و توفير وسائل امان و سلامة للتونجر | V21: الادارة الهندسية | W21: 27/1/2023 | X21: yes | Y21: Closed | Z21: م/ادهم مصطفى | AA21: 29/1/2023 | AB21: ok
A22: =A21+1 -> 19 | B22: 44927 | C22: 44938 | D22: تفتيش داخلى | G22: 44938 | H22: -4 | J22: عنبر ويب2 | K22: لوحات ويب 11 | L22: الادارة الهندسية | P22: مخلفات خشبية وورقية واسلاك كهربائية بجوار لوح كهرباء ويب11 | Q22: عدم ترتيب و تنظيم | R22: أولى | S22: متوسط | T22: OK | U22: المتابعة الدورية لصيانة المنشأة ومتابعة نظافة العنابر | V22: الادارة الهندسية | W22: 27/1/2023 | X22: end | Y22: Closed | Z22: م/ادهم مصطفى | AA22: 27/1/2023 | AB22: ok
A23: =A22+1 -> 20 | B23: 44927 | C23: 44938 | D23: تفتيش داخلى | G23: 44938 | H23: -5 | J23: عنبر ويب2 | K23: ويب 11 و 10 | L23: الادارة الهندسية | P23: وجود مخلفات لقطع غيار تالفة اسفل ويب 11.10 | Q23: عدم ترتيب و تنظيم | R23: أولى | S23: متوسط | T23: OK | U23: المتابعة الدورية لصيانةونظافة الماكينة و حول الماكينة | V23: الادارة الهندسية | W23: 27/1/2023 | X23: end | Y23: Closed | Z23: م/ادهم مصطفى | AA23: 27/1/2023 | AB23: ok
A24: =A23+1 -> 21 | B24: 44927 | C24: 44938 | D24: تفتيش داخلى | G24: 44938 | H24: -6 | J24: عنبر ويب2 | K24: لوحات ويب 10 | L24: الادارة الهندسية | P24: عدم احكام وغلق اسفل لوحات الكهرباء بجوار ويب 10 | Q24: وضع غير أمن | R24: أولى | S24: متوسط | T24: OK | U24: المتابعة الدورية لصيانة المنشأة | V24: الادارة الهندسية | W24: 27/1/2023 | X24: end | Y24: Closed | Z24: م/ادهم مصطفى | AA24: 27/1/2023 | AB24: ok
A25: =A24+1 -> 22 | B25: 44927 | C25: 44938 | D25: تفتيش داخلى | G25: 44938 | H25: -7 | J25: عنبر ويب2 | K25: ويب10 | L25: الادارة الهندسية | P25: تسريب سائل من مواسير ويب 10 على لوحة كهرباء | Q25: وضع غير أمن | R25: أولى | S25: عالي | T25: OK | U25: المتابعة الدورية لصيانة الماكينة | V25: الادارة الهندسية | W25: 29/1/2023 | X25: end | Y25: Closed | Z25: م/ادهم مصطفى | AA25: 29/1/2023 | AB25: ok
A26: =A25+1 -> 23 | B26: 44927 | C26: 44938 | D26: تفتيش داخلى | G26: 44938 | H26: -8 | J26: عنبر ويب2 | K26: فرن | L26: الادارة الهندسية | P26: استخدام فرن بدرجات حرارة عالية وبجوار مخلفات ورقية لويب 11 وبدون استخدام وسائل امان للفرن | Q26: وضع غير أمن | R26: أولى | S26: متوسط | T26: OK | U26: تغيير مكان الفرن و استخدام وسائل حماية و امان للافراد وتوعية العاملين بمخاطر تشغيل الفرن | V26: الادارة الهندسية | X26: yes | Y26: Opened | Z26: م/ادهم مصطفى | AB26: DELAYED
A27: =A26+1 -> 24 | B27: 44927 | C27: 44945 | D27: حادث وشيك | G27: 44945 | H27: -1 | J27: عنبر ويب1 | K27: ويب4 | L27: الادارة الهندسية | P27: انزلاق البكر من على عربة المشاية الخاصة بنقل البكر من منطقة التخزين لرفعها على الماكينة | Q27: وضع غير أمن | R27: ليلية | S27: متوسط | T27: OK | U27: تركيب حواجز بصدادات ارضية بجوار العربة | V27: الادارة الهندسية | W27: 45017 | X27: end | Y27: Closed | Z27: م/ادهم مصطفى | AA27: 45017 | AB27: DELAYED
A28: =A27+1 -> 25 | B28: 44927 | C28: 44949 | D28: تفتيش داخلى | G28: 44949 | H28: -1 | J28: المخزن الجديد | K28: عنبر 3 | L28: المخازن | P28: محبس حريق 2.5 بوصة و صندوق الحريق اعلى 3 كابلات كهرباء المغذية للعنبر | Q28: وضع غير أمن | R28: أولى | S28: متوسط | T28: OK | U28: تعديل اي من صندوق الحريق او مسار الكابلات | V28: الشؤون الادارية | W28: 45102 | X28: end | Y28: Closed | Z28: هاني لطفي | AA28: 45102 | AB28: DELAYED
A29: =A28+1 -> 26 | B29: 44927 | C29: 23/1/2023 | D29: تفتيش داخلى | G29: 44949 | H29: -2 | J29: المخزن الجديد | K29: عنبر 1 | L29: المخازن | P29: فيش كهرباء خارجية في الشارع الجانبي لعنبر 1 مكسورة و بها كهرباء | Q29: وضع غير أمن | R29: أولى | S29: متوسط | T29: OK | U29: تغيير اي فيش كهرباء تالفه واستبدالها باخرى معتمدة و مؤمنة | V29: الشؤون الادارية | W29: 45102 | X29: end | Y29: Closed | Z29: هاني لطفي | AA29: 45102 | AB29: DELAYED
A30: =A29+1 -> 27 | B30: 44927 | C30: 23/1/2023 | D30: تفتيش داخلى | G30: 44949 | H30: -3 | J30: المكابس | K30: المكبس | L30: الادارة الهندسية | P30: وجود لوحة كهرباء خاصة بالمكبس تحتاج الى قفل | Q30: وضع غير أمن | R30: أولى | S30: متوسط | T30: OK | U30: يجب عمل قفل على لوحة الكهرباء الخاصة بالمكبس | V30: الادارة الهندسية | W30: 29/1/2023 | X30: end | Y30: Closed | Z30: م/ادهم مصطفى | AA30: 29/1/2023 | AB30: ok
A31: =A30+1 -> 28 | B31: 44927 | C31: 23/1/2023 | D31: تفتيش داخلى | G31: 44949 | H31: -4 | J31: عنبر ويب2 | K31: ويب 11 | L31: الادارة الهندسية | P31: وجود زيت و مياه في الترى الخاص بالكابلات الكهربائية | Q31: وضع غير أمن | R31: ليلية | S31: متوسط | T31: OK | U31: تنظيف المكان في اسرع وقت ومتابعة دورية | V31: الادارة الهندسية | W31: 23/1/2023 | X31: end | Y31: Closed | Z31: م/ادهم مصطفى | AA31: 29/1/2023 | AB31: ok
A32: =A31+1 -> 29 | B32: 44927 | C32: 23/1/2023 | D32: تفتيش داخلى | G32: 44949 | H32: -5 | J32: عنبر ويب 3 | K32: حمامات عنبر ويب 3 | L32: الشؤون الادارية | P32: حمامات عنبر ويب 3 تحتاج الى تنظيف جيد | Q32: وضع غير أمن | R32: ليلية | S32: متوسط | T32: OK | U32: تنظيف الحمامات باستمرار و المتابعة الدورية عليها | V32: الشؤون الادارية | W32: 23/1/2023 | X32: end | Y32: Closed | Z32: احمد مرسي | AA32: 23/1/2023 | AB32: OK
A33: =A32+1 -> 30 | B33: 44927 | C33: 24/1/2023 | D33: تفتيش داخلى | G33: 44950 | H33: -1 | J33: عنبر ويب2 | K33: تنك الاحبار لويب 10 | L33: الادارة الهندسية | P33: وجود توصيلات كهرباء عشوائية خاصة ببستم و تنك الاحبار | Q33: وضع غير أمن | R33: أولى | S33: متوسط | T33: OK | U33: توصيل بشكل جيد او تريه خاص به | V33: الادارة الهندسية | W33: 14/2/2023 | X33: end | Y33: Closed | Z33: م/ادهم مصطفى | AA33: 14/2/2023 | AB33: ok
A34: =A33+1 -> 31 | B34: 44927 | C34: 24/1/2023 | D34: تفتيش داخلى | G34: 44950 | H34: -2 | J34: عنبر ويب 3 | K34: المسجد | L34: الادارة الهندسية | P34: وجود كابلات عشوائية خاصة بسماعة المسجد بجوار ويب 2 | Q34: وضع غير أمن | R34: أولى | S34: متوسط | T34: OK | U34: توصيل الكابلات بشكل امن | V34: الشؤون الادارية | W34: 14/2/2023 | X34: end | Y34: Closed | Z34: م/ادهم مصطفى | AA34: 14/2/2023 | AB34: ok
A35: =A34+1 -> 32 | B35: 44927 | C35: 27/1/2023 | D35: تفتيش داخلى | G35: 44953 | H35: -1 | J35: المخزن الجديد | K35: المخزن الجديد | L35: الادارة الهندسية | P35: وجود كابل كهرباء 3 فاز خارج الحائط بدون عزل | Q35: وضع غير أمن | R35: أولى | S35: عالي | T35: OK | U35: عزل كابل الكهرباء | V35: الادارة الهندسية | W35: 27/1/2023 | X35: end | Y35: Closed | Z35: م/ادهم مصطفى | AA35: 27/1/2023 | AB35: ok
A36: =A35+1 -> 33 | B36: 44927 | C36: 30/1/2023 | D36: تفتيش داخلى | G36: 44956 | H36: -1 | J36: المكاتب الادارية | K36: الخزينة | L36: الشؤون الادارية | P36: وجود مشترك كهرباء بالممر بجانب مكتب امين الخزينة | Q36: وضع غير أمن | R36: أولى | S36: متوسط | T36: OK | U36: تغير و تعديل المشترك باخر مناسب | V36: الشؤون الادارية | W36: 14/2/2023 | X36: yes | Y36: Closed | Z36: م/ادهم مصطفى | AA36: 14/2/2023 | AB36: ok
A37: =A36+1 -> 34 | B37: 44927 | C37: 30/1/2023 | D37: حادث وشيك | G37: 44956 | H37: -2 | J37: المخزن القديم | K37: مبيت الامن | L37: الشؤون الادارية | P37: سقف مبيت الامن معرض للسقوط و غير مسموح بالعمل تحته | Q37: وضع غير أمن | R37: أولى | S37: عالي | T37: OK | U37: تقرير فني لتوضيح اعمال الصيانة للسقف و ترميمه ( تم ابلاغ شركة اوزوريون لعمل التقرير ) | V37: الشؤون الادارية | W37: 45102 | X37: yes | Y37: Closed | Z37: م/ادهم مصطفى | AA37: 45102 | AB37: dELAYED
A38: =A37+1 -> 35 | B38: 44958 | C38: 45171 | D38: تفتيش داخلى | G38: 44966 | H38: -3 | J38: المخزن الجديد | K38: امام عنبر 1 | L38: المخازن | P38: وجود تنكات السولار امام عنبر 1 | Q38: وضع غير أمن | R38: أولى | S38: متوسط | T38: OK | U38: نقل تنكات السولار في مكان امن داخل المخزن الجديد | V38: المخازن | W38: 45171 | X38: End | Y38: Closed | Z38: م/ادهم مصطفى | AA38: 45171 | AB38: ok
A39: =A38+1 -> 36 | B39: 44958 | C39: 45171 | D39: تفتيش داخلى | G39: 44966 | H39: -4 | J39: المخزن الجديد | K39: خزان الحريق | L39: السلامة و الصحة | P39: عدم وجود عوامة في خزان مياه الحريق | Q39: وضع غير أمن | R39: أولى | S39: متوسط | T39: OK | U39: تركيب عوامة لخزان المياه الخاص بشبكة الحريق | V39: السلامة و الصحة | W39: 45171 | X39: End | Y39: Closed | Z39: م/ادهم مصطفى | AA39: 45171 | AB39: ok
A40: =A39+1 -> 37 | B40: 44958 | C40: 16/2/2023 | D40: تفتيش داخلى | G40: 44973 | H40: -1 | J40: المخزن القديم | K40: غرفة مولد الديزل | L40: الادارة الهندسية | P40: وجود بواط تجميع كابلات كهرباء بجوار ماسورة مدخنة الديزل وكابل تشغيل باور لوحة الإنذار بغرفتين الكهرباء و الديزل يمر بفتحة المدخنة بالقرب من ماسورة العادم | Q40: وضع غير أمن | R40: أولى | S40: متوسط | T40: OK | U40: تعديل بواط الكهرباء ومسار الكابل بعيدا عن اي مصدر حرارة | V40: الادارة الهندسية | W40: 45078 | X40: end | Y40: Closed | Z40: م/ادهم مصطفى | AA40: 45078 | AB40: DELAYED
A41: =A40+1 -> 38 | B41: 44958 | C41: 16/2/2023 | D41: تفتيش داخلى | G41: 44973 | H41: -2 | J41: عنبر ويب 3 | K41: سطح العنبر | L41: الادارة الهندسية | P41: مروحة شفاط تحتاج ال شبكة حماية | Q41: وضع غير أمن | R41: أولى | S41: متوسط | T41: OK | U41: تركيب شبكة حماية لتجنب دخول طيور او قوارض و تلفها | V41: الادارة الهندسية | W41: 45111 | X41: YES | Y41: Closed | Z41: م/ادهم مصطفى | AA41: 45111 | AB41: DELAYED
A42: =A41+1 -> 39 | B42: 44958 | C42: 22/2/2023 | D42: تفتيش داخلى | G42: 44979 | H42: -1 | J42: الساحة الاماية بالمطابع | K42: سلم مدفع الحريق | L42: الادارة الهندسية | P42: كسر في الدرجة الأولى من سلم مدفع الحريق الموجود في الساحة امام بوابة الأمن | Q42: وضع غير أمن | R42: أولى | S42: منخفض | T42: OK | U42: صيانة السلم ولحام الدرجة المكسورة | V42: الادارة الهندسية | W42: 45021 | X42: End | Y42: Closed | Z42: م/ادهم مصطفى | AA42: 45021 | AB42: DELAYED
...
